order-book/a1-a2-testcases/hard-random-1.in

    # Random heavily threaded test case
    
40
o
0 S 0 AMZN 6473 5
0 S 1 GOOG 2806 4
0 S 2 AMZN 2094 4
0 C 2
0 B 3 GOOG 5166 17
0 B 4 AMZN 4880 10
0 S 5 AMZN 8286 7
0 C 5
0 B 6 AMZN 7140 7
0 S 7 AMZN 6886 9
0 S 8 AAPL 8948 16
0 S 9 AMZN 6280 7
0 B 10 GOOG 2331 1
0 S 11 AMZN 1158 18
0 S 12 AMZN 2795 14
0 S 13 AAPL 7533 13
0 S 14 AMZN 3288 8
0 B 15 AAPL 6203 4
0 C 7
0 B 16 AMZN 4351 19
0 B 17 GOOG 8531 16
0 C 6
0 B 18 AMZN 7454 11
0 C 11
0 B 19 AAPL 7528 11
0 C 10
0 S 20 AAPL 4146 4
0 S 21 AAPL 4897 9
0 S 22 GOOG 7370 9
0 C 3
0 B 23 AAPL 3021 20
0 B 24 AAPL 1103 13
0 S 25 GOOG 6902 3
0 B 26 AMZN 7395 2
0 B 27 GOOG 3621 15
0 B 28 AMZN 1723 10
0 C 23
0 S 29 GOOG 4836 19
0 C 22
0 B 30 AMZN 4958 13
0 S 31 AAPL 1725 18
0 B 32 AMZN 6933 9
0 S 33 GOOG 6442 9
0 S 34 GOOG 6950 3
0 S 35 GOOG 5161 7
0 S 36 GOOG 3393 18
0 C 15
0 C 0
0 C 2
0 S 37 GOOG 3106 16
0 S 38 AAPL 6689 13
0 B 39 AAPL 5076 5
0 C 20
0 B 40 AAPL 3616 15
0 B 41 AMZN 5643 4
0 S 42 AAPL 3081 5
0 B 43 AMZN 4766 18
0 S 44 AMZN 3159 17
0 S 45 GOOG 1260 14
0 S 46 AAPL 2728 19
0 B 47 GOOG 2486 4
0 S 48 AAPL 1919 10
0 C 37
0 S 49 GOOG 8004 2
0 C 1
0 C 2
0 S 50 GOOG 5574 10
0 S 51 AMZN 2568 6
0 B 52 AMZN 4908 16
0 B 53 AMZN 6840 5
0 S 54 GOOG 2554 19
0 C 38
0 B 55 AMZN 4621 18
0 B 56 AMZN 2424 8
0 S 57 GOOG 6559 2
0 B 58 AAPL 1295 1
0 B 59 AAPL 7372 11
0 B 60 AAPL 3916 4
0 C 4
0 C 21
0 C 41
0 B 61 GOOG 4463 13
0 C 19
0 S 62 GOOG 8271 5
0 B 63 AAPL 5517 2
0 S 64 AAPL 7465 17
0 S 65 AMZN 5635 3
0 S 66 AAPL 4241 2
0 S 67 AMZN 4602 18
0 B 68 AMZN 8353 20
0 S 69 AAPL 4429 1
0 S 70 AAPL 8685 1
0 B 71 AMZN 4931 1
0 B 72 AMZN 2351 19
0 C 31
0 B 73 AAPL 8702 13
0 B 74 GOOG 4751 17
0 C 53
0 B 75 AMZN 4574 15
0 B 76 AMZN 5470 17
0 C 45
0 S 77 GOOG 3949 2
0 S 78 GOOG 6416 14
0 S 79 AAPL 2668 8
0 C 56
0 B 80 AAPL 8390 15
0 C 28
0 C 75
0 C 49
0 C 26
0 S 81 AMZN 5821 7
0 C 65
0 S 82 GOOG 3960 10
0 S 83 AMZN 4622 17
0 B 84 AMZN 2200 13
0 B 85 AAPL 2432 10
0 S 86 GOOG 6567 12
0 B 87 GOOG 4550 11
0 C 22
0 C 37
0 S 88 GOOG 5535 2
0 B 89 AMZN 1661 2
0 C 36
0 S 90 AMZN 4142 17
0 S 91 GOOG 5617 10
0 S 92 AAPL 1751 20
0 S 93 AMZN 7714 18
0 C 91
0 S 94 GOOG 4544 1
0 C 88
0 S 95 GOOG 8296 10
0 C 34
0 B 96 AAPL 5524 17
0 S 97 GOOG 7426 18
0 C 34
0 C 32
0 S 98 AAPL 2832 4
0 S 99 GOOG 6026 12
0 C 54
0 S 100 GOOG 5399 19
0 S 101 AAPL 8721 13
0 C 74
0 C 21
0 C 43
0 S 102 GOOG 5738 18
0 S 103 AMZN 7176 12
0 C 31
0 B 104 GOOG 8400 6
0 S 105 GOOG 8282 13
0 B 106 AMZN 5006 2
0 B 107 GOOG 1080 18
0 B 108 AAPL 4203 11
0 C 98
0 S 109 GOOG 7254 4
0 C 41
0 B 110 GOOG 3662 3
0 B 111 GOOG 8763 17
0 S 112 AMZN 6265 13
0 S 113 GOOG 8819 17
0 B 114 AAPL 6484 11
0 C 39
0 B 115 AMZN 5297 15
0 S 116 GOOG 5075 15
0 C 97
0 S 117 GOOG 1611 18
0 C 16
0 B 118 GOOG 5096 10
0 C 63
0 B 119 GOOG 1569 6
0 C 10
0 C 106
0 S 120 AMZN 4788 3
0 C 103
0 S 121 AAPL 3298 13
0 S 122 AMZN 2553 2
0 S 123 AAPL 8952 1
0 B 124 GOOG 7474 11
0 C 19
0 C 81
0 S 125 AAPL 7653 12
0 S 126 AMZN 1240 18
0 C 34
0 S 127 AMZN 3389 4
0 C 16
0 C 2
0 S 128 AAPL 2037 11
0 B 129 AAPL 4229 5
0 S 130 GOOG 4625 1
0 S 131 GOOG 7917 3
0 B 132 AAPL 1699 15
0 C 42
0 B 133 AAPL 2911 1
0 C 14
0 S 134 AMZN 6561 13
0 B 135 AAPL 1130 14
0 B 136 AAPL 4103 6
0 S 137 AMZN 1528 10
0 S 138 AMZN 6773 13
0 S 139 AAPL 8920 10
0 B 140 AAPL 7917 3
0 S 141 AAPL 1044 3
0 B 142 AAPL 8646 19
0 S 143 AMZN 6482 4
0 C 91
0 B 144 GOOG 8110 7
0 C 92
0 B 145 AMZN 6556 3
0 B 146 AMZN 2101 17
0 B 147 AAPL 1757 12
0 S 148 AMZN 2929 17
0 S 149 AAPL 4264 13
0 B 150 AAPL 8200 14
0 S 151 GOOG 4909 1
0 C 59
0 B 152 GOOG 7766 20
0 B 153 AMZN 8678 6
0 B 154 GOOG 8565 16
0 B 155 AAPL 6255 6
0 S 156 AMZN 4940 3
0 S 157 AMZN 8797 12
0 C 65
0 C 30
0 B 158 AMZN 7731 4
0 S 159 GOOG 7992 16
0 B 160 AAPL 1357 5
0 C 103
0 S 161 GOOG 4342 13
0 C 91
0 S 162 GOOG 1113 15
0 C 18
0 S 163 GOOG 5369 3
0 S 164 GOOG 3211 8
0 B 165 GOOG 3860 10
0 B 166 AMZN 1912 19
0 S 167 AMZN 2465 9
0 B 168 GOOG 3318 12
0 B 169 AAPL 4446 5
0 S 170 GOOG 7209 14
0 B 171 AMZN 3922 3
0 S 172 AMZN 3125 1
0 S 173 GOOG 7603 13
0 S 174 AMZN 8856 9
0 C 151
0 C 9
0 C 101
0 B 175 GOOG 2946 5
0 S 176 GOOG 2035 16
0 B 177 GOOG 5604 19
0 S 178 GOOG 4927 2
0 S 179 AAPL 4822 11
0 B 180 AMZN 3518 3
0 S 181 GOOG 1987 1
0 C 181
0 S 182 AAPL 2519 4
0 B 183 AMZN 8854 7
0 C 169
0 S 184 AMZN 4337 5
0 B 185 AMZN 5955 11
0 B 186 AMZN 7720 9
0 B 187 GOOG 8695 3
0 B 188 AMZN 6477 19
0 B 189 GOOG 6273 19
0 S 190 AAPL 7227 7
0 B 191 AMZN 7100 6
0 C 57
0 S 192 GOOG 4423 12
0 S 193 AAPL 6545 18
0 S 194 AAPL 4992 8
0 C 61
0 S 195 GOOG 3093 9
0 B 196 AMZN 7825 9
0 C 46
0 S 197 AMZN 8448 14
0 B 198 AMZN 5727 20
0 S 199 AAPL 4479 5
0 B 200 AMZN 6114 11
0 S 201 AMZN 5915 11
0 C 132
0 B 202 GOOG 5664 20
0 C 23
0 B 203 AAPL 5113 16
0 S 204 AAPL 6562 14
0 B 205 AAPL 6533 6
0 S 206 AAPL 3997 9
0 S 207 AMZN 8094 3
0 C 50
0 B 208 AMZN 2825 19
0 S 209 AMZN 6573 20
0 C 100
0 C 168
0 B 210 AAPL 3313 15
0 C 175
0 S 211 AMZN 4388 10
0 C 61
0 B 212 AMZN 6514 18
0 S 213 AMZN 7661 9
0 S 214 AAPL 5325 7
0 S 215 GOOG 6039 7
0 C 173
0 S 216 AAPL 6332 17
0 C 170
0 B 217 AAPL 6151 2
0 C 42
0 S 218 GOOG 7451 19
0 B 219 AAPL 5129 1
0 B 220 GOOG 2276 19
0 S 221 GOOG 3268 14
0 B 222 AMZN 3489 4
0 B 223 AMZN 5146 18
0 S 224 GOOG 6586 16
0 S 225 GOOG 8586 1
0 S 226 AMZN 3456 6
0 B 227 AAPL 7400 18
0 C 171
0 S 228 GOOG 4269 10
0 B 229 AAPL 1765 9
0 C 5
0 B 230 AAPL 1523 13
0 B 231 GOOG 6635 3
0 B 232 GOOG 3493 13
0 C 45
0 S 233 AMZN 6608 4
0 S 234 AAPL 1590 17
0 S 235 AMZN 5384 19
0 B 236 GOOG 3391 1
0 C 211
0 S 237 AMZN 3504 4
0 B 238 AAPL 7322 1
0 S 239 AMZN 4423 18
0 C 49
0 S 240 AMZN 4373 17
0 C 214
0 B 241 AMZN 4608 6
0 C 142
0 C 46
0 S 242 AAPL 8704 19
0 B 243 AAPL 4961 3
0 B 244 GOOG 4235 6
0 C 134
0 S 245 GOOG 7597 3
0 S 246 GOOG 7276 18
0 B 247 GOOG 4830 7
0 B 248 GOOG 8486 6
0 B 249 AAPL 1575 16
0 B 250 AMZN 7823 13
0 C 132
0 S 251 GOOG 5176 10
0 C 222
0 S 252 GOOG 6118 5
0 S 253 GOOG 1796 4
0 C 209
0 B 254 AMZN 7280 1
0 B 255 AAPL 3946 6
0 C 96
0 B 256 GOOG 3436 15
0 S 257 AAPL 8318 2
0 B 258 AMZN 4064 1
0 S 259 GOOG 2304 2
0 C 126
0 S 260 AMZN 8200 9
0 B 261 GOOG 6441 2
0 S 262 AAPL 5375 15
0 B 263 GOOG 3806 18
0 S 264 GOOG 2834 17
0 B 265 AMZN 7239 2
0 C 175
0 B 266 AAPL 6975 3
0 B 267 AAPL 7705 18
0 C 109
0 B 268 GOOG 8533 18
0 S 269 AMZN 7406 6
0 C 229
0 S 270 AMZN 7126 1
0 S 271 AAPL 1800 4
0 C 203
0 B 272 AAPL 1319 8
0 S 273 AAPL 6376 13
0 S 274 GOOG 6629 2
0 C 133
0 B 275 GOOG 7707 11
0 S 276 AMZN 5501 16
0 S 277 GOOG 2143 14
0 B 278 GOOG 8762 3
0 B 279 AAPL 8507 14
0 C 113
0 S 280 GOOG 8048 15
0 C 218
0 B 281 GOOG 2093 6
0 S 282 GOOG 7912 18
0 S 283 AAPL 8725 13
0 C 162
0 B 284 AAPL 4213 13
0 S 285 AMZN 6241 14
0 S 286 AMZN 7447 10
0 S 287 AMZN 4992 3
0 S 288 GOOG 5711 10
0 S 289 AMZN 4944 4
0 C 235
0 C 283
0 B 290 GOOG 5475 11
0 C 48
0 C 112
0 C 84
0 C 161
0 S 291 GOOG 5922 7
0 B 292 AMZN 8876 4
0 S 293 AMZN 5897 11
0 C 57
0 C 258
0 C 157
0 S 294 AMZN 7610 3
0 B 295 AMZN 7441 15
0 B 296 AAPL 1534 5
0 B 297 GOOG 1052 13
0 C 142
0 B 298 GOOG 5496 5
0 S 299 AAPL 7738 18
0 C 20
0 C 137
0 B 300 GOOG 1102 9
0 S 301 AAPL 2636 10
0 S 302 AMZN 1095 2
0 C 258
0 B 303 AMZN 4113 13
0 C 24
0 B 304 AMZN 8314 14
0 S 305 AMZN 6704 19
0 C 42
0 B 306 AMZN 3378 20
0 S 307 GOOG 3634 7
0 C 205
0 S 308 GOOG 2950 14
0 B 309 AMZN 5824 17
0 S 310 GOOG 3543 3
0 B 311 AMZN 7495 15
0 C 211
0 C 94
0 S 312 AAPL 1504 20
0 C 198
0 C 6
0 B 313 AMZN 6601 20
0 B 314 AAPL 2578 7
0 B 315 GOOG 3012 8
0 C 63
0 C 303
0 B 316 AMZN 5236 7
0 B 317 GOOG 1110 6
0 B 318 GOOG 5807 20
0 S 319 AMZN 8333 1
0 S 320 AMZN 4916 6
0 S 321 AAPL 4911 3
0 C 307
0 B 322 GOOG 6390 19
0 S 323 AMZN 6399 15
0 C 202
0 S 324 AMZN 6856 8
0 S 325 AMZN 2153 20
0 C 184
0 B 326 GOOG 8164 20
0 B 327 AAPL 6938 13
0 S 328 AMZN 2928 5
0 S 329 GOOG 1473 14
0 S 330 GOOG 3876 15
0 C 291
0 B 331 GOOG 3991 14
0 C 5
0 B 332 GOOG 1319 17
0 S 333 GOOG 2487 16
0 C 293
0 C 109
0 C 283
0 B 334 AMZN 4183 6
0 B 335 AMZN 6698 11
0 C 279
0 C 80
0 S 336 AAPL 4874 15
0 C 225
0 C 125
0 C 336
0 C 300
0 C 333
0 S 337 AAPL 6222 16
0 S 338 GOOG 4318 9
0 B 339 GOOG 4255 11
0 S 340 GOOG 7608 4
0 S 341 AAPL 8425 11
