order-book/a1-a2-testcases/hard-random-2.in

    # Random heavily threaded test case, periodic full clean to keep order book small
    
40
o
0 B 0 AAPL 7866 19
0 B 1 AAPL 5554 9
0 B 2 AMZN 8300 7
0 C 2
0 B 3 GOOG 3516 15
0 B 4 AMZN 5325 1
0 S 5 GOOG 1097 12
0 B 6 AAPL 1675 13
0 C 2
0 C 0
0 C 5
0 C 1
0 S 7 AAPL 3859 4
0 S 8 GOOG 5886 9
0 S 9 AMZN 5969 14
0 S 10 AAPL 1123 5
0 S 11 AMZN 1987 1
0 C 8
0 C 4
0 S 12 AAPL 8438 17
0 B 13 AMZN 6378 20
0 B 14 AMZN 7899 18
0 C 0
0 S 15 GOOG 2703 3
0 S 16 GOOG 8076 9
0 C 0
0 C 2
0 S 17 GOOG 7378 4
0 B 18 AMZN 7055 17
0 C 12
1 B 19 GOOG 7342 11
1 B 20 GOOG 7883 16
1 B 21 GOOG 2475 12
1 B 22 AMZN 1353 4
1 B 23 AMZN 6450 12
1 B 24 AAPL 8127 19
1 B 25 GOOG 2283 14
1 S 26 GOOG 4871 8
1 B 27 GOOG 3496 18
1 C 25
1 S 28 AMZN 8237 14
1 S 29 GOOG 1453 4
1 S 30 GOOG 5605 7
1 S 31 GOOG 6365 14
1 S 32 GOOG 8121 12
1 B 33 GOOG 4023 20
1 C 32
1 C 28
1 C 20
1 B 34 GOOG 7042 18
1 S 35 AAPL 8643 9
1 C 23
1 C 25
1 S 36 GOOG 1241 20
1 B 37 AAPL 3690 11
1 B 38 AAPL 6457 1
1 S 39 AAPL 6843 13
1 B 40 GOOG 8265 9
1 C 28
1 C 25
2 S 41 AAPL 6352 4
2 B 42 AMZN 6686 10
2 B 43 GOOG 3363 12
2 C 41
2 B 44 AMZN 3132 20
2 C 42
2 S 45 GOOG 4448 3
2 C 42
2 S 46 GOOG 3912 15
2 S 47 GOOG 6442 11
2 B 48 GOOG 4314 14
2 C 48
2 C 48
2 B 49 AAPL 3644 1
2 B 50 GOOG 7096 8
2 C 47
2 B 51 GOOG 2496 16
2 B 52 AAPL 4293 16
2 B 53 AAPL 5486 14
2 B 54 GOOG 3574 3
2 B 55 AMZN 4173 18
2 B 56 AAPL 3635 5
2 B 57 GOOG 8998 10
2 S 58 AMZN 3088 6
2 B 59 AAPL 8187 4
2 C 47
2 S 60 GOOG 1148 8
2 B 61 AMZN 5236 3
2 B 62 AMZN 4171 17
2 B 63 AMZN 3092 3
3 S 64 AAPL 7626 18
3 C 64
3 B 65 GOOG 3178 11
3 S 66 AAPL 6764 12
3 C 65
3 S 67 GOOG 1115 6
3 C 66
3 S 68 AAPL 3288 20
3 B 69 GOOG 1930 2
3 B 70 AAPL 4338 12
3 B 71 AAPL 8151 6
3 S 72 AMZN 3472 4
3 S 73 AMZN 7925 3
3 B 74 AMZN 7483 14
3 S 75 GOOG 1612 16
3 C 67
3 S 76 AMZN 2203 18
3 C 75
3 C 75
3 B 77 AMZN 2436 7
3 B 78 AMZN 8642 11
3 C 72
3 B 79 AAPL 8150 8
3 B 80 GOOG 5165 19
3 S 81 AAPL 8435 17
3 B 82 GOOG 1316 17
3 C 68
3 S 83 GOOG 1633 1
3 B 84 GOOG 4734 7
3 B 85 GOOG 8590 19
4 S 86 GOOG 3292 17
4 B 87 AAPL 8364 20
4 C 86
4 B 88 AMZN 1831 15
4 C 86
4 C 87
4 S 89 AMZN 6748 14
4 S 90 GOOG 6388 17
4 S 91 AAPL 1684 15
4 S 92 AAPL 5119 17
4 S 93 AAPL 6878 8
4 S 94 AMZN 5710 2
4 C 92
4 C 87
4 C 88
4 S 95 AMZN 2309 11
4 B 96 AAPL 1984 1
4 S 97 AMZN 4905 12
4 S 98 AMZN 6764 19
4 S 99 AMZN 3413 17
4 S 100 AAPL 2254 9
4 S 101 AMZN 2462 14
4 C 94
4 B 102 AMZN 2269 10
4 S 103 AMZN 4418 7
4 B 104 AAPL 2085 19
4 S 105 AAPL 8684 17
4 B 106 GOOG 6120 6
4 B 107 AAPL 5748 3
4 B 108 AAPL 4182 17
5 B 109 GOOG 5652 20
5 C 109
5 B 110 GOOG 8330 3
5 B 111 GOOG 7832 13
5 S 112 AAPL 7910 8
5 B 113 GOOG 5385 10
5 B 114 AMZN 5141 5
5 S 115 AMZN 5698 14
5 S 116 GOOG 4736 5
5 S 117 AAPL 6123 9
5 C 114
5 C 109
5 C 111
5 S 118 AMZN 2570 9
5 S 119 AMZN 1022 18
5 B 120 GOOG 6991 5
5 C 118
5 S 121 GOOG 4269 14
5 C 109
5 B 122 GOOG 6802 9
5 C 110
5 B 123 AAPL 5165 6
5 C 116
5 B 124 AAPL 5783 9
5 B 125 GOOG 7807 3
5 S 126 GOOG 6710 4
5 B 127 GOOG 7791 9
5 B 128 AMZN 5614 15
5 S 129 AAPL 5345 13
5 S 130 AMZN 7382 17
6 S 131 AMZN 2573 9
6 C 131
6 S 132 AAPL 5871 14
6 C 131
6 C 132
6 B 133 AAPL 1518 20
6 B 134 AMZN 1956 6
6 C 133
6 B 135 GOOG 7160 5
6 C 133
6 S 136 GOOG 3853 19
6 S 137 AMZN 6132 6
6 C 134
6 B 138 AMZN 3112 11
6 B 139 AMZN 1749 18
6 C 138
6 C 137
6 C 135
6 S 140 AMZN 2431 16
6 B 141 AMZN 1872 11
6 C 139
6 B 142 GOOG 8252 10
6 C 142
6 C 137
6 C 139
6 C 138
6 C 136
6 C 136
6 C 135
6 C 142
7 S 143 AMZN 3178 4
7 S 144 AAPL 1644 12
7 C 144
7 B 145 AAPL 5823 11
7 S 146 GOOG 6056 8
7 B 147 GOOG 8672 15
7 B 148 GOOG 4817 14
7 C 148
7 S 149 AMZN 8959 16
7 B 150 AMZN 5715 15
7 C 149
7 S 151 AAPL 3573 18
7 S 152 AAPL 1804 15
7 C 148
7 B 153 AAPL 6918 2
7 C 145
7 S 154 AAPL 1561 5
7 B 155 GOOG 6203 9
7 B 156 AMZN 5197 18
7 S 157 GOOG 2647 4
7 C 157
7 B 158 GOOG 2421 20
7 B 159 GOOG 6933 1
7 B 160 GOOG 8620 14
7 B 161 AMZN 2527 8
7 C 155
7 C 143
7 B 162 AMZN 6742 8
7 B 163 GOOG 4157 20
7 C 146
8 S 164 AAPL 7980 11
8 B 165 GOOG 6766 11
8 C 164
8 C 164
8 S 166 AMZN 8056 2
8 S 167 GOOG 6909 13
8 C 164
8 C 165
8 B 168 AMZN 2951 3
8 C 166
8 C 166
8 S 169 AMZN 8310 6
8 S 170 GOOG 3433 11
8 B 171 AMZN 6485 5
8 B 172 GOOG 7087 11
8 B 173 AMZN 6233 15
8 C 173
8 S 174 AMZN 5046 3
8 S 175 AAPL 4441 16
8 S 176 GOOG 7966 3
8 B 177 AAPL 8580 10
8 S 178 GOOG 3946 1
8 C 177
8 S 179 AMZN 6666 9
8 S 180 AMZN 1130 14
8 S 181 GOOG 2666 5
8 B 182 AAPL 3847 11
8 B 183 GOOG 5247 14
8 S 184 GOOG 6235 13
8 S 185 AAPL 1702 5
9 B 186 AAPL 4377 8
9 B 187 AAPL 8579 8
9 C 187
9 C 186
9 B 188 AMZN 2304 14
9 C 186
9 B 189 AAPL 7860 1
9 B 190 AAPL 6641 17
9 S 191 GOOG 1895 13
9 C 187
9 B 192 GOOG 4057 20
9 C 191
9 S 193 GOOG 8194 18
9 B 194 AMZN 2927 8
9 B 195 AAPL 6522 20
9 B 196 GOOG 6244 9
9 S 197 GOOG 2578 18
9 S 198 AMZN 4019 12
9 C 194
9 C 186
9 C 195
9 S 199 AAPL 2716 14
9 C 194
9 S 200 AAPL 2773 16
9 C 197
9 C 194
9 C 193
9 B 201 AMZN 6716 4
9 B 202 AMZN 4877 14
9 S 203 AMZN 2643 7
10 S 204 AAPL 3410 13
10 S 205 AAPL 1321 1
10 S 206 AAPL 5819 7
10 C 205
10 B 207 AAPL 7193 2
10 C 205
10 B 208 AAPL 7083 20
10 S 209 GOOG 4270 14
10 B 210 GOOG 6652 16
10 B 211 AMZN 7066 16
10 B 212 GOOG 5260 7
10 B 213 GOOG 5666 8
10 S 214 AAPL 4518 5
10 B 215 AMZN 7848 9
10 S 216 GOOG 8981 1
10 S 217 AAPL 2907 9
10 S 218 AAPL 7674 3
10 S 219 AMZN 3526 7
10 B 220 AAPL 8647 2
10 B 221 GOOG 4699 12
10 S 222 AAPL 7099 2
10 S 223 AAPL 5484 17
10 C 217
10 B 224 GOOG 4136 9
10 S 225 GOOG 7660 10
10 C 211
10 C 210
10 C 221
10 S 226 AMZN 6610 3
10 B 227 AMZN 4845 15
11 S 228 AAPL 7609 20
11 S 229 AMZN 1538 12
11 B 230 AMZN 4403 17
11 B 231 GOOG 5857 7
11 S 232 AMZN 7103 3
11 C 229
11 B 233 GOOG 1790 14
11 S 234 AAPL 6877 11
11 C 233
11 B 235 AAPL 3745 8
11 B 236 GOOG 3245 4
11 S 237 AAPL 8832 12
11 C 237
11 S 238 GOOG 4004 12
11 S 239 AAPL 8306 13
11 B 240 AAPL 6730 18
11 C 237
11 B 241 GOOG 6290 6
11 B 242 GOOG 6070 4
11 B 243 GOOG 3724 4
11 C 241
11 C 236
11 B 244 GOOG 1982 7
11 B 245 AAPL 7566 11
11 B 246 AMZN 1921 3
11 C 240
11 S 247 GOOG 1677 12
11 S 248 AAPL 3548 12
11 S 249 AAPL 1745 15
11 S 250 AMZN 3441 18
12 B 251 GOOG 1256 2
12 S 252 AMZN 4031 13
12 B 253 GOOG 2962 17
12 B 254 GOOG 4684 10
12 S 255 GOOG 1533 6
12 C 253
12 B 256 GOOG 4358 7
12 C 253
12 C 252
12 B 257 AMZN 6300 7
12 C 252
12 C 257
12 C 255
12 S 258 GOOG 1022 4
12 S 259 AMZN 5888 20
12 C 251
12 C 259
12 B 260 GOOG 8316 20
12 C 257
12 B 261 GOOG 3960 8
12 B 262 AMZN 8103 3
12 C 259
12 S 263 AMZN 8145 18
12 S 264 GOOG 8318 14
12 S 265 GOOG 5501 3
12 C 264
12 S 266 AMZN 6303 20
12 C 266
12 B 267 AMZN 8015 12
12 B 268 GOOG 5026 6
13 B 269 GOOG 4889 14
13 S 270 GOOG 6009 2
13 C 269
13 B 271 AMZN 2389 3
13 C 271
13 S 272 AMZN 6742 6
13 C 271
13 S 273 GOOG 6509 7
13 S 274 GOOG 8386 10
13 B 275 GOOG 6464 8
13 B 276 AMZN 2096 13
13 C 276
13 S 277 AMZN 7672 7
13 S 278 AMZN 8933 15
13 B 279 AMZN 7012 6
13 S 280 GOOG 8053 20
13 S 281 AMZN 6720 6
13 S 282 GOOG 3855 7
13 S 283 GOOG 8483 17
13 C 271
13 C 271
13 C 279
13 S 284 GOOG 8013 14
13 S 285 GOOG 3779 19
13 S 286 GOOG 1516 1
13 B 287 AAPL 3884 14
13 B 288 AMZN 3687 3
13 C 278
13 B 289 AAPL 4430 15
13 B 290 GOOG 5333 6
14 S 291 GOOG 7476 18
14 S 292 AAPL 8455 1
14 S 293 AMZN 2517 3
14 C 293
14 B 294 GOOG 2903 19
14 B 295 GOOG 2923 19
14 S 296 GOOG 7335 5
14 S 297 GOOG 4083 2
14 B 298 GOOG 3878 15
14 S 299 AAPL 3873 2
14 B 300 GOOG 6034 12
14 B 301 GOOG 8608 10
14 S 302 AMZN 2841 11
14 S 303 GOOG 8974 3
14 C 295
14 S 304 AMZN 8136 18
14 C 298
14 S 305 AAPL 3630 15
14 B 306 GOOG 7225 11
14 B 307 AMZN 3330 9
14 S 308 AAPL 4740 6
14 C 299
14 C 304
14 C 299
14 C 302
14 S 309 GOOG 8269 9
14 S 310 AAPL 6887 10
14 S 311 AMZN 4173 8
14 C 291
14 S 312 AAPL 3652 10
15 S 313 AMZN 1788 7
15 B 314 AAPL 8433 6
15 S 315 AMZN 8662 2
15 S 316 GOOG 8684 4
15 B 317 GOOG 7200 17
15 S 318 AMZN 5289 19
15 C 314
15 S 319 AMZN 2928 15
15 S 320 AAPL 2226 19
15 B 321 GOOG 4548 11
15 B 322 GOOG 3068 20
15 C 318
15 C 316
15 C 320
15 S 323 AAPL 6093 15
15 S 324 AMZN 2988 6
15 C 322
15 S 325 GOOG 8286 15
15 B 326 AMZN 4353 19
15 C 326
15 S 327 AMZN 6517 17
15 S 328 GOOG 6630 10
